<?xml version="1.0" ?>
<robot name="partnet_1cd18c195955ea78598a453fd9fbd988">
	<link name="base"/>
	<link name="link_0">
		<visual name="outside_frame-1">
			<origin xyz="0 0 0"/>
			<geometry>
				<mesh filename="textured_objs/original-3.obj"/>
			</geometry>
		</visual>
		<visual name="outside_frame-1">
			<origin xyz="0 0 0"/>
			<geometry>
				<mesh filename="textured_objs/original-4.obj"/>
			</geometry>
		</visual>
		<collision>
			<origin xyz="0 0 0"/>
			<geometry>
				<mesh filename="textured_objs/original-3.obj"/>
			</geometry>
		</collision>
		<collision>
			<origin xyz="0 0 0"/>
			<geometry>
				<mesh filename="textured_objs/original-4.obj"/>
			</geometry>
		</collision>
	</link>
	<joint name="joint_0" type="fixed">
		<origin rpy="1.570796326794897 0 -1.570796326794897" xyz="0 0 0"/>
		<child link="link_0"/>
		<parent link="base"/>
	</joint>
	<link name="link_1">
		<visual name="surface_board-16">
			<origin xyz="0.4066634119514137 -0.8931909999999998 -0.003700144325522514"/>
			<geometry>
				<mesh filename="textured_objs/original-7.obj"/>
			</geometry>
		</visual>
		<visual name="surface_board-16">
			<origin xyz="0.4066634119514137 -0.8931909999999998 -0.003700144325522514"/>
			<geometry>
				<mesh filename="textured_objs/new-3.obj"/>
			</geometry>
		</visual>
		<visual name="surface_board-16">
			<origin xyz="0.4066634119514137 -0.8931909999999998 -0.003700144325522514"/>
			<geometry>
				<mesh filename="textured_objs/new-0.obj"/>
			</geometry>
		</visual>
		<visual name="surface_board-16">
			<origin xyz="0.4066634119514137 -0.8931909999999998 -0.003700144325522514"/>
			<geometry>
				<mesh filename="textured_objs/new-4.obj"/>
			</geometry>
		</visual>
		<visual name="surface_board-16">
			<origin xyz="0.4066634119514137 -0.8931909999999998 -0.003700144325522514"/>
			<geometry>
				<mesh filename="textured_objs/original-11.obj"/>
			</geometry>
		</visual>
		<visual name="surface_board-16">
			<origin xyz="0.4066634119514137 -0.8931909999999998 -0.003700144325522514"/>
			<geometry>
				<mesh filename="textured_objs/original-14.obj"/>
			</geometry>
		</visual>
		<visual name="surface_board-16">
			<origin xyz="0.4066634119514137 -0.8931909999999998 -0.003700144325522514"/>
			<geometry>
				<mesh filename="textured_objs/original-8.obj"/>
			</geometry>
		</visual>
		<visual name="surface_board-16">
			<origin xyz="0.4066634119514137 -0.8931909999999998 -0.003700144325522514"/>
			<geometry>
				<mesh filename="textured_objs/original-13.obj"/>
			</geometry>
		</visual>
		<visual name="surface_board-16">
			<origin xyz="0.4066634119514137 -0.8931909999999998 -0.003700144325522514"/>
			<geometry>
				<mesh filename="textured_objs/original-17.obj"/>
			</geometry>
		</visual>
		<visual name="surface_board-16">
			<origin xyz="0.4066634119514137 -0.8931909999999998 -0.003700144325522514"/>
			<geometry>
				<mesh filename="textured_objs/new-1.obj"/>
			</geometry>
		</visual>
		<visual name="surface_board-16">
			<origin xyz="0.4066634119514137 -0.8931909999999998 -0.003700144325522514"/>
			<geometry>
				<mesh filename="textured_objs/original-9.obj"/>
			</geometry>
		</visual>
		<visual name="surface_board-16">
			<origin xyz="0.4066634119514137 -0.8931909999999998 -0.003700144325522514"/>
			<geometry>
				<mesh filename="textured_objs/new-2.obj"/>
			</geometry>
		</visual>
		<visual name="surface_board-16">
			<origin xyz="0.4066634119514137 -0.8931909999999998 -0.003700144325522514"/>
			<geometry>
				<mesh filename="textured_objs/original-10.obj"/>
			</geometry>
		</visual>
		<visual name="surface_board-16">
			<origin xyz="0.4066634119514137 -0.8931909999999998 -0.003700144325522514"/>
			<geometry>
				<mesh filename="textured_objs/original-16.obj"/>
			</geometry>
		</visual>
		<visual name="surface_board-16">
			<origin xyz="0.4066634119514137 -0.8931909999999998 -0.003700144325522514"/>
			<geometry>
				<mesh filename="textured_objs/original-15.obj"/>
			</geometry>
		</visual>
		<visual name="surface_board-16">
			<origin xyz="0.4066634119514137 -0.8931909999999998 -0.003700144325522514"/>
			<geometry>
				<mesh filename="textured_objs/original-12.obj"/>
			</geometry>
		</visual>
		<collision>
			<origin xyz="0.4066634119514137 -0.8931909999999998 -0.003700144325522514"/>
			<geometry>
				<mesh filename="textured_objs/original-7.obj"/>
			</geometry>
		</collision>
		<collision>
			<origin xyz="0.4066634119514137 -0.8931909999999998 -0.003700144325522514"/>
			<geometry>
				<mesh filename="textured_objs/new-3.obj"/>
			</geometry>
		</collision>
		<collision>
			<origin xyz="0.4066634119514137 -0.8931909999999998 -0.003700144325522514"/>
			<geometry>
				<mesh filename="textured_objs/new-0.obj"/>
			</geometry>
		</collision>
		<collision>
			<origin xyz="0.4066634119514137 -0.8931909999999998 -0.003700144325522514"/>
			<geometry>
				<mesh filename="textured_objs/new-4.obj"/>
			</geometry>
		</collision>
		<collision>
			<origin xyz="0.4066634119514137 -0.8931909999999998 -0.003700144325522514"/>
			<geometry>
				<mesh filename="textured_objs/original-11.obj"/>
			</geometry>
		</collision>
		<collision>
			<origin xyz="0.4066634119514137 -0.8931909999999998 -0.003700144325522514"/>
			<geometry>
				<mesh filename="textured_objs/original-14.obj"/>
			</geometry>
		</collision>
		<collision>
			<origin xyz="0.4066634119514137 -0.8931909999999998 -0.003700144325522514"/>
			<geometry>
				<mesh filename="textured_objs/original-8.obj"/>
			</geometry>
		</collision>
		<collision>
			<origin xyz="0.4066634119514137 -0.8931909999999998 -0.003700144325522514"/>
			<geometry>
				<mesh filename="textured_objs/original-13.obj"/>
			</geometry>
		</collision>
		<collision>
			<origin xyz="0.4066634119514137 -0.8931909999999998 -0.003700144325522514"/>
			<geometry>
				<mesh filename="textured_objs/original-17.obj"/>
			</geometry>
		</collision>
		<collision>
			<origin xyz="0.4066634119514137 -0.8931909999999998 -0.003700144325522514"/>
			<geometry>
				<mesh filename="textured_objs/new-1.obj"/>
			</geometry>
		</collision>
		<collision>
			<origin xyz="0.4066634119514137 -0.8931909999999998 -0.003700144325522514"/>
			<geometry>
				<mesh filename="textured_objs/original-9.obj"/>
			</geometry>
		</collision>
		<collision>
			<origin xyz="0.4066634119514137 -0.8931909999999998 -0.003700144325522514"/>
			<geometry>
				<mesh filename="textured_objs/new-2.obj"/>
			</geometry>
		</collision>
		<collision>
			<origin xyz="0.4066634119514137 -0.8931909999999998 -0.003700144325522514"/>
			<geometry>
				<mesh filename="textured_objs/original-10.obj"/>
			</geometry>
		</collision>
		<collision>
			<origin xyz="0.4066634119514137 -0.8931909999999998 -0.003700144325522514"/>
			<geometry>
				<mesh filename="textured_objs/original-16.obj"/>
			</geometry>
		</collision>
		<collision>
			<origin xyz="0.4066634119514137 -0.8931909999999998 -0.003700144325522514"/>
			<geometry>
				<mesh filename="textured_objs/original-15.obj"/>
			</geometry>
		</collision>
		<collision>
			<origin xyz="0.4066634119514137 -0.8931909999999998 -0.003700144325522514"/>
			<geometry>
				<mesh filename="textured_objs/original-12.obj"/>
			</geometry>
		</collision>
	</link>
	<joint name="joint_1" type="revolute">
		<origin xyz="-0.4066634119514137 0.8931909999999998 0.003700144325522514"/>
		<axis xyz="0 -1 0"/>
		<child link="link_1"/>
		<parent link="link_0"/>
		<limit lower="0.0" upper="1.5707963267948966"/>
	</joint>
	<link name="link_2">
		<visual name="fixed_part-5">
			<origin xyz="-0.3412588668976835 0.06464413310231656 0"/>
			<geometry>
				<mesh filename="textured_objs/original-23.obj"/>
			</geometry>
		</visual>
		<visual name="fixed_part-5">
			<origin xyz="-0.3412588668976835 0.06464413310231656 0"/>
			<geometry>
				<mesh filename="textured_objs/original-22.obj"/>
			</geometry>
		</visual>
		<visual name="fixed_part-6">
			<origin xyz="-0.3412588668976835 0.06464413310231656 0"/>
			<geometry>
				<mesh filename="textured_objs/original-19.obj"/>
			</geometry>
		</visual>
		<visual name="fixed_part-6">
			<origin xyz="-0.3412588668976835 0.06464413310231656 0"/>
			<geometry>
				<mesh filename="textured_objs/original-20.obj"/>
			</geometry>
		</visual>
		<collision>
			<origin xyz="-0.3412588668976835 0.06464413310231656 0"/>
			<geometry>
				<mesh filename="textured_objs/original-23.obj"/>
			</geometry>
		</collision>
		<collision>
			<origin xyz="-0.3412588668976835 0.06464413310231656 0"/>
			<geometry>
				<mesh filename="textured_objs/original-22.obj"/>
			</geometry>
		</collision>
		<collision>
			<origin xyz="-0.3412588668976835 0.06464413310231656 0"/>
			<geometry>
				<mesh filename="textured_objs/original-19.obj"/>
			</geometry>
		</collision>
		<collision>
			<origin xyz="-0.3412588668976835 0.06464413310231656 0"/>
			<geometry>
				<mesh filename="textured_objs/original-20.obj"/>
			</geometry>
		</collision>
	</link>
	<joint name="joint_2" type="continuous">
		<origin xyz="0.7479222788490971 -0.9578351331023164 -0.003700144325522514"/>
		<axis xyz="0 0 1"/>
		<child link="link_2"/>
		<parent link="link_1"/>
	</joint>
</robot>
